10:28:44 PM:DEBUG [logger_base.py:14] Mensaje a nivel debug
10:28:44 PM:INFO [logger_base.py:15] Mensaje a nivel info
10:28:44 PM:WARNING [logger_base.py:16] Mensaje a nivel warning
10:28:44 PM:ERROR [logger_base.py:17] Mensaje a nivel error
10:28:44 PM:CRITICAL [logger_base.py:18] Mensaje a nivel critical
10:56:33 PM:DEBUG [Persona.py:53] 
Id Persona: 1, Nombre: Juan, Apellido: Perez, Email: jperez@mail.com

10:58:52 PM:DEBUG [Persona.py:53] 
Id Persona: 1, Nombre: Juan, Apellido: Perez, Email: jperez@mail.com

11:00:55 PM:DEBUG [Persona.py:53] 
Id Persona: 1, Nombre: Juan, Apellido: Perez, Email: jperez@mail.com

11:00:55 PM:DEBUG [Persona.py:55] 
Id Persona: Jose, Nombre: Lepez, Apellido: ljose@mail.com, Email: None

11:04:24 PM:DEBUG [Persona.py:53] 
Id Persona: 1, Nombre: Juan, Apellido: Perez, Email: jperez@mail.com

11:04:24 PM:DEBUG [Persona.py:55] 
Id Persona: None, Nombre: Jose, Apellido: Lepez, Email: ljose@mail.com

11:04:24 PM:DEBUG [Persona.py:57] 
Id Persona: 1, Nombre: None, Apellido: None, Email: None

11:31:44 PM:DEBUG [conexion.py:25] Conexión Exitosa: <connection object at 0x000001A78FBD59C0; dsn: 'user=postgres password=xxx dbname=test_bd host=127.0.0.1 port=5432', closed: 0>
11:33:47 PM:ERROR [conexion.py:28] Ocurrió un error: connection to server at "127.0.0.1", port 5432 failed: FATAL:  password authentication failed for user "postgres"

11:34:51 PM:DEBUG [conexion.py:25] Conexión Exitosa: <connection object at 0x00000171E60259C0; dsn: 'user=postgres password=xxx dbname=test_bd host=127.0.0.1 port=5432', closed: 0>
11:34:51 PM:DEBUG [conexion.py:38] Se abrió correctamente el cursor: <cursor object at 0x00000171E5D525E0; closed: 0>
